Workbook

Sheet Assumptions
A1: GLOW BEAUTY — ALL ASSUMPTIONS
A2: Change any value in columns B/C — the model recalculates from these.
A4: PRODUCT
B5: Conservative | C5: Optimistic | D5: Why
A6: Avg product price | B6: 65 | C6: 65 | D6: Premium beauty: $45-85 range
A7: Avg PV per active rep/month | B7: 250 | C7: 500 | D7: Conservative = autoship + light selling. Optimistic = active sellers.
A8: Min autoship to stay active | B8: 150 | C8: 150 | D8: Monthly purchase required to earn commissions
A9: Product COGS (% of revenue) | B9: 0.2 | C9: 0.2 | D9: Cost to manufacture/source product
A10: Shipping & ops (% of revenue) | B10: 0.1 | C10: 0.1 | D10: Fulfillment, packaging, logistics
A12: CHURN & RETENTION
B13: Conservative | C13: Optimistic | D13: Why
A14: Monthly churn: Months 1-3 | B14: 0.08 | C14: 0.05 | D14: The danger zone. Most quits happen here.
A15: Monthly churn: Months 4-12 | B15: 0.04 | C15: 0.025 | D15: Settled in but still fragile
A16: Monthly churn: Month 13+ | B16: 0.02 | C16: 0.012 | D16: Long-term steady state
A17: 12-month survival rate | B17: =((1-B14)^3)*((1-B15)^9) | C17: =((1-C14)^3)*((1-C15)^9) | D17: % of a cohort still active after 12 months
A18: 24-month survival rate | B18: =B17*((1-B16)^12) | C18: =C17*((1-C16)^12) | D18: % still active after 24 months
A20: RECRUITING & GROWTH
B21: Conservative | C21: Optimistic | D21: Why
A22: Your direct recruits (L1) by end Y1 | B22: 4 | C22: 8 | D22: Cumulative people YOU personally recruit
A23: Your direct recruits (L1) by end Y2 | B23: 8 | C23: 15
A24: Your direct recruits (L1) by end Y3 | B24: 12 | C24: 25
A25: Your direct recruits (L1) by end Y4 | B25: 15 | C25: 30
A26: Avg recruits per rep (fanout) | B26: 2 | C26: 3.5 | D26: Each rep recruits this many people on average over their lifetime
A27: Months before a new rep starts recruiting | B27: 3 | C27: 2 | D27: Ramp time before a rep starts bringing in their own recruits
A29: COMPENSATION PLAN
A30: Component | B30: Rate | C30: Unlock Requirement | D30: Notes
A31: Retail commission | B31: 25% | C31: Everyone | D31: On personal sales
A32: L1 override | B32: 10% | C32: Starter: recruit 1 | D32: On direct recruits' sales
A33: L2 override | B33: 5% | C33: Builder: recruit 3
A34: L3 override | B34: 4% | C34: Leader: 5 recruits + $5k GV
A35: L4 override | B35: 3% | C35: Director: $25k GV
A36: L5 override | B36: 2% | C36: Sr. Director: $75k GV
A37: L6 override | B37: 1% | C37: VP: $200k GV
A38: L7 override | B38: 1% | C38: Founder's Circle: $500k GV
A39: Leadership pool: Director | B39: 1% of co. revenue | C39: Split among Directors only | D39: Separate pool per rank
A40: Leadership pool: Sr. Director | B40: +1% of co. revenue | C40: Split among Sr. Directors only
A41: Leadership pool: VP | B41: +1% of co. revenue | C41: Split among VPs only
A42: Leadership pool: FC | B42: +1% of co. revenue | C42: Split among FCs only
A43: Founding 20 bonus | B43: 1% of co. revenue | C43: Original 20 only | D43: ÷ 20, forever, if active
A45: MAX THEORETICAL PAYOUT | B45: 25% + 26% + 4% + 1% = 56% | D45: Actual will be ~40-48% because most reps don't unlock all levels

Sheet Churn Model
A1: MONTHLY CHURN MODEL — COHORT TRACKING
A2: Shows how a cohort of 100 reps decays over 24 months
A4: CONSERVATIVE SCENARIO
A5: Month | B5: Start of Month | C5: Churn Rate | D5: Churned Out | E5: End of Month | F5: Formula
A6: 1 | B6: 100 | C6: 0.08 | D6: =ROUND(B6*C6,1) | E6: =B6-D6 | F6: Months 1-3: 8%/mo (danger zone)
A7: 2 | B7: =E6 | C7: 0.08 | D7: =ROUND(B7*C7,1) | E7: =B7-D7 | F7: Months 1-3: 8%/mo (danger zone)
A8: 3 | B8: =E7 | C8: 0.08 | D8: =ROUND(B8*C8,1) | E8: =B8-D8 | F8: Months 1-3: 8%/mo (danger zone)
A9: 4 | B9: =E8 | C9: 0.04 | D9: =ROUND(B9*C9,1) | E9: =B9-D9 | F9: Months 4-12: 4%/mo (settling in)
A10: 5 | B10: =E9 | C10: 0.04 | D10: =ROUND(B10*C10,1) | E10: =B10-D10
A11: 6 | B11: =E10 | C11: 0.04 | D11: =ROUND(B11*C11,1) | E11: =B11-D11
A12: 7 | B12: =E11 | C12: 0.04 | D12: =ROUND(B12*C12,1) | E12: =B12-D12
A13: 8 | B13: =E12 | C13: 0.04 | D13: =ROUND(B13*C13,1) | E13: =B13-D13
A14: 9 | B14: =E13 | C14: 0.04 | D14: =ROUND(B14*C14,1) | E14: =B14-D14
A15: 10 | B15: =E14 | C15: 0.04 | D15: =ROUND(B15*C15,1) | E15: =B15-D15
A16: 11 | B16: =E15 | C16: 0.04 | D16: =ROUND(B16*C16,1) | E16: =B16-D16
A17: 12 | B17: =E16 | C17: 0.04 | D17: =ROUND(B17*C17,1) | E17: =B17-D17
A18: 13 | B18: =E17 | C18: 0.02 | D18: =ROUND(B18*C18,1) | E18: =B18-D18 | F18: Months 13+: 2%/mo (steady state)
A19: 14 | B19: =E18 | C19: 0.02 | D19: =ROUND(B19*C19,1) | E19: =B19-D19
A20: 15 | B20: =E19 | C20: 0.02 | D20: =ROUND(B20*C20,1) | E20: =B20-D20
A21: 16 | B21: =E20 | C21: 0.02 | D21: =ROUND(B21*C21,1) | E21: =B21-D21
A22: 17 | B22: =E21 | C22: 0.02 | D22: =ROUND(B22*C22,1) | E22: =B22-D22
A23: 18 | B23: =E22 | C23: 0.02 | D23: =ROUND(B23*C23,1) | E23: =B23-D23
A24: 19 | B24: =E23 | C24: 0.02 | D24: =ROUND(B24*C24,1) | E24: =B24-D24
A25: 20 | B25: =E24 | C25: 0.02 | D25: =ROUND(B25*C25,1) | E25: =B25-D25
A26: 21 | B26: =E25 | C26: 0.02 | D26: =ROUND(B26*C26,1) | E26: =B26-D26
A27: 22 | B27: =E26 | C27: 0.02 | D27: =ROUND(B27*C27,1) | E27: =B27-D27
A28: 23 | B28: =E27 | C28: 0.02 | D28: =ROUND(B28*C28,1) | E28: =B28-D28
A29: 24 | B29: =E28 | C29: 0.02 | D29: =ROUND(B29*C29,1) | E29: =B29-D29
A31: SUMMARY
A32: After 3 months: | B32: =E8 | C32: out of 100
A33: After 12 months: | B33: =E17 | C33: out of 100
A34: After 24 months: | B34: =E29 | C34: out of 100
A37: OPTIMISTIC SCENARIO
A38: Month | B38: Start of Month | C38: Churn Rate | D38: Churned Out | E38: End of Month | F38: Formula
A39: 1 | B39: 100 | C39: 0.05 | D39: =ROUND(B39*C39,1) | E39: =B39-D39 | F39: Months 1-3: 5%/mo (better onboarding)
A40: 2 | B40: =E39 | C40: 0.05 | D40: =ROUND(B40*C40,1) | E40: =B40-D40 | F40: Months 1-3: 5%/mo (better onboarding)
A41: 3 | B41: =E40 | C41: 0.05 | D41: =ROUND(B41*C41,1) | E41: =B41-D41 | F41: Months 1-3: 5%/mo (better onboarding)
A42: 4 | B42: =E41 | C42: 0.025 | D42: =ROUND(B42*C42,1) | E42: =B42-D42 | F42: Months 4-12: 2.5%/mo
A43: 5 | B43: =E42 | C43: 0.025 | D43: =ROUND(B43*C43,1) | E43: =B43-D43
A44: 6 | B44: =E43 | C44: 0.025 | D44: =ROUND(B44*C44,1) | E44: =B44-D44
...

Sheet Conservative
A1: FOUNDING GLOW GIRL — CONSERVATIVE ($250 avg PV, high churn)
A2: Avg PV: $250/mo | Your PV: $800/mo | 12mo survival: 47%
A4: YOUR ORGANIZATION (bottom-up with churn)
B5: Year 1 | C5: Year 2 | D5: Year 3 | E5: Year 4 | F5: Formula / Notes
A6: Gross L1 recruits (cumulative) | B6: 4 | C6: 8 | D6: 12 | E6: 15 | F6: Total people YOU have ever recruited
A8: ACTIVE REPS BY LEVEL (after churn)
A9: L1: Your direct recruits (net) | B9: 1 | C9: 2 | D9: 4 | E9: 5 | F9: Gross × survival rate. Override: 10%
A10: L2: Their recruits (net) | B10: 5 | C10: 7 | D10: 8 | E10: 10 | F10: Gross × survival rate. Override: 5%
A11: L3 (net) | B11: 0 | C11: 15 | D11: 16 | E11: 20 | F11: Gross × survival rate. Override: 4%
A12: L4 (net) | B12: 0 | C12: 47 | D12: 45 | E12: 40 | F12: Gross × survival rate. Override: 3%
A13: L5 (net) | B13: 0 | C13: 0 | D13: 90 | E13: 81 | F13: Gross × survival rate. Override: 2%
A14: L6 (net) | B14: 0 | C14: 0 | D14: 282 | E14: 225 | F14: Gross × survival rate. Override: 1%
A15: L7 (net) | B15: 0 | C15: 0 | D15: 0 | E15: 451 | F15: Gross × survival rate. Override: 1%
A16: TOTAL ACTIVE ORG SIZE | B16: =SUM(B9:B15) | C16: =SUM(C9:C15) | D16: =SUM(D9:D15) | E16: =SUM(E9:E15) | F16: =Sum of all active reps across levels
A17: Your org monthly GV | B17: =B16*250 | C17: =C16*250 | D17: =D16*250 | E17: =E16*250 | F17: =Active org × $250 avg PV
A19: ESTIMATED COMPANY TOTALS
B20: Year 1 | C20: Year 2 | D20: Year 3 | E20: Year 4 | F20: Formula / Notes
A21: Total company reps (20 founders × avg) | B21: =B16*15 | C21: =C16*15 | D21: =D16*15 | E21: =E16*15 | F21: ~15× your org (not all founders build equally)
A22: Monthly company revenue | B22: =B21*250 | C22: =C21*250 | D22: =D21*250 | E22: =E21*250 | F22: =Total reps × $250
A23: Annual company revenue | B23: =B22*12 | C23: =C22*12 | D23: =D22*12 | E23: =E22*12 | F23: =Monthly × 12
A25: YOUR MONTHLY EARNINGS
B26: Year 1 | C26: Year 2 | D26: Year 3 | E26: Year 4 | F26: Formula / Notes
A27: Personal sales (25%) | B27: 200 | C27: 200 | D27: 200 | E27: 200 | F27: =$800 your PV × 25%
A28: L1 override (10%) | B28: =B9*250*0.1 | C28: =C9*250*0.1 | D28: =D9*250*0.1 | E28: =E9*250*0.1 | F28: =L1 active reps × $250 × 10%
A29: L2 override (5%) | B29: =B10*250*0.05 | C29: =C10*250*0.05 | D29: =D10*250*0.05 | E29: =E10*250*0.05 | F29: =L2 active reps × $250 × 5%
A30: L3 override (4%) | B30: =B11*250*0.04 | C30: =C11*250*0.04 | D30: =D11*250*0.04 | E30: =E11*250*0.04 | F30: =L3 active reps × $250 × 4%
A31: L4 override (3%) | B31: =B12*250*0.03 | C31: =C12*250*0.03 | D31: =D12*250*0.03 | E31: =E12*250*0.03 | F31: =L4 active reps × $250 × 3%
A32: L5 override (2%) | B32: =B13*250*0.02 | C32: =C13*250*0.02 | D32: =D13*250*0.02 | E32: =E13*250*0.02 | F32: =L5 active reps × $250 × 2%
A33: L6 override (1%) | B33: =B14*250*0.01 | C33: =C14*250*0.01 | D33: =D14*250*0.01 | E33: =E14*250*0.01 | F33: =L6 active reps × $250 × 1%
A34: L7 override (1%) | B34: =B15*250*0.01 | C34: =C15*250*0.01 | D34: =D15*250*0.01 | E34: =E15*250*0.01 | F34: =L7 active reps × $250 × 1%
A35: SUBTOTAL: Overrides | B35: =SUM(B28:B34) | C35: =SUM(C28:C34) | D35: =SUM(D28:D34) | E35: =SUM(E28:E34)
A37: Leadership pool share | B37: 0 | C37: =C22*0.01/5 | D37: =D22*0.02/15 | E37: =E22*0.03/30 | F37: =Company rev × rank pool % ÷ # leaders at your rank
A38: Your rank | B38: Builder | C38: Director | D38: Sr. Director | E38: VP
A39: Leaders sharing this pool | B39: 1 | C39: 5 | D39: 15 | E39: 30
A41: Founding 20 bonus (1% ÷ 20) | B41: =B22*0.01/20 | C41: =C22*0.01/20 | D41: =D22*0.01/20 | E41: =E22*0.01/20 | F41: =1% of company monthly revenue ÷ 20 founders
A43: MONTHLY TOTAL | B43: =B27+B35+B37+B41 | C43: =C27+C35+C37+C41 | D43: =D27+D35+D37+D41 | E43: =E27+E35+E37+E41
A44: ANNUAL TOTAL | B44: =B43*12 | C44: =C43*12 | D44: =D43*12 | E44: =E43*12
A46: SANITY CHECKS
A47: CHECK 1: Total payout ratio
A48: Est. total commissions (all reps) | B48: =B22*0.45 | C48: =C22*0.45 | D48: =D22*0.45 | E48: =E22*0.45 | F48: Estimated at ~45% of revenue (retail + overrides + pools)
...

Sheet Optimistic
A1: FOUNDING GLOW GIRL — OPTIMISTIC ($500 avg PV, low churn)
A2: Avg PV: $500/mo | Your PV: $1500/mo | 12mo survival: 65%
A4: YOUR ORGANIZATION (bottom-up with churn)
B5: Year 1 | C5: Year 2 | D5: Year 3 | E5: Year 4 | F5: Formula / Notes
A6: Gross L1 recruits (cumulative) | B6: 8 | C6: 15 | D6: 25 | E6: 30 | F6: Total people YOU have ever recruited
A8: ACTIVE REPS BY LEVEL (after churn)
A9: L1: Your direct recruits (net) | B9: 5 | C9: 7 | D9: 13 | E9: 15 | F9: Gross × survival rate. Override: 10%
A10: L2: Their recruits (net) | B10: 23 | C10: 33 | D10: 45 | E10: 54 | F10: Gross × survival rate. Override: 5%
A11: L3 (net) | B11: 0 | C11: 118 | D11: 158 | E11: 190 | F11: Gross × survival rate. Override: 4%
A12: L4 (net) | B12: 0 | C12: 525 | D12: 691 | E12: 667 | F12: Gross × survival rate. Override: 3%
A13: L5 (net) | B13: 0 | C13: 0 | D13: 2420 | E13: 2336 | F13: Gross × survival rate. Override: 2%
A14: L6 (net) | B14: 0 | C14: 0 | D14: 10753 | E14: 10223 | F14: Gross × survival rate. Override: 1%
A15: L7 (net) | B15: 0 | C15: 0 | D15: 0 | E15: 35783 | F15: Gross × survival rate. Override: 1%
A16: TOTAL ACTIVE ORG SIZE | B16: =SUM(B9:B15) | C16: =SUM(C9:C15) | D16: =SUM(D9:D15) | E16: =SUM(E9:E15) | F16: =Sum of all active reps across levels
A17: Your org monthly GV | B17: =B16*500 | C17: =C16*500 | D17: =D16*500 | E17: =E16*500 | F17: =Active org × $500 avg PV
A19: ESTIMATED COMPANY TOTALS
B20: Year 1 | C20: Year 2 | D20: Year 3 | E20: Year 4 | F20: Formula / Notes
A21: Total company reps (20 founders × avg) | B21: =B16*15 | C21: =C16*15 | D21: =D16*15 | E21: =E16*15 | F21: ~15× your org (not all founders build equally)
A22: Monthly company revenue | B22: =B21*500 | C22: =C21*500 | D22: =D21*500 | E22: =E21*500 | F22: =Total reps × $500
A23: Annual company revenue | B23: =B22*12 | C23: =C22*12 | D23: =D22*12 | E23: =E22*12 | F23: =Monthly × 12
A25: YOUR MONTHLY EARNINGS
B26: Year 1 | C26: Year 2 | D26: Year 3 | E26: Year 4 | F26: Formula / Notes
A27: Personal sales (25%) | B27: 375 | C27: 375 | D27: 375 | E27: 375 | F27: =$1500 your PV × 25%
A28: L1 override (10%) | B28: =B9*500*0.1 | C28: =C9*500*0.1 | D28: =D9*500*0.1 | E28: =E9*500*0.1 | F28: =L1 active reps × $500 × 10%
A29: L2 override (5%) | B29: =B10*500*0.05 | C29: =C10*500*0.05 | D29: =D10*500*0.05 | E29: =E10*500*0.05 | F29: =L2 active reps × $500 × 5%
A30: L3 override (4%) | B30: =B11*500*0.04 | C30: =C11*500*0.04 | D30: =D11*500*0.04 | E30: =E11*500*0.04 | F30: =L3 active reps × $500 × 4%
A31: L4 override (3%) | B31: =B12*500*0.03 | C31: =C12*500*0.03 | D31: =D12*500*0.03 | E31: =E12*500*0.03 | F31: =L4 active reps × $500 × 3%
A32: L5 override (2%) | B32: =B13*500*0.02 | C32: =C13*500*0.02 | D32: =D13*500*0.02 | E32: =E13*500*0.02 | F32: =L5 active reps × $500 × 2%
A33: L6 override (1%) | B33: =B14*500*0.01 | C33: =C14*500*0.01 | D33: =D14*500*0.01 | E33: =E14*500*0.01 | F33: =L6 active reps × $500 × 1%
A34: L7 override (1%) | B34: =B15*500*0.01 | C34: =C15*500*0.01 | D34: =D15*500*0.01 | E34: =E15*500*0.01 | F34: =L7 active reps × $500 × 1%
A35: SUBTOTAL: Overrides | B35: =SUM(B28:B34) | C35: =SUM(C28:C34) | D35: =SUM(D28:D34) | E35: =SUM(E28:E34)
A37: Leadership pool share | B37: 0 | C37: =C22*0.01/5 | D37: =D22*0.02/15 | E37: =E22*0.03/30 | F37: =Company rev × rank pool % ÷ # leaders at your rank
A38: Your rank | B38: Builder | C38: Director | D38: Sr. Director | E38: VP
A39: Leaders sharing this pool | B39: 1 | C39: 5 | D39: 15 | E39: 30
A41: Founding 20 bonus (1% ÷ 20) | B41: =B22*0.01/20 | C41: =C22*0.01/20 | D41: =D22*0.01/20 | E41: =E22*0.01/20 | F41: =1% of company monthly revenue ÷ 20 founders
A43: MONTHLY TOTAL | B43: =B27+B35+B37+B41 | C43: =C27+C35+C37+C41 | D43: =D27+D35+D37+D41 | E43: =E27+E35+E37+E41
A44: ANNUAL TOTAL | B44: =B43*12 | C44: =C43*12 | D44: =D43*12 | E44: =E43*12
A46: SANITY CHECKS
A47: CHECK 1: Total payout ratio
A48: Est. total commissions (all reps) | B48: =B22*0.45 | C48: =C22*0.45 | D48: =D22*0.45 | E48: =E22*0.45 | F48: Estimated at ~45% of revenue (retail + overrides + pools)
...

Sheet Comparison
A1: SIDE-BY-SIDE COMPARISON
B3: Cons Y1 | C3: Opt Y1 | D3: Cons Y2 | E3: Opt Y2 | F3: Cons Y3 | G3: Opt Y3 | H3: Cons Y4 | I3: Opt Y4
A4: Your active org size | B4: =Conservative!B16 | C4: =Optimistic!B16 | D4: =Conservative!C16 | E4: =Optimistic!C16 | F4: =Conservative!D16 | G4: =Optimistic!D16 | H4: =Conservative!E16 | I4: =Optimistic!E16
A5: Your org monthly GV | B5: =Conservative!B17 | C5: =Optimistic!B17 | D5: =Conservative!C17 | E5: =Optimistic!C17 | F5: =Conservative!D17 | G5: =Optimistic!D17 | H5: =Conservative!E17 | I5: =Optimistic!E17
A6: Monthly company revenue | B6: =Conservative!B22 | C6: =Optimistic!B22 | D6: =Conservative!C22 | E6: =Optimistic!C22 | F6: =Conservative!D22 | G6: =Optimistic!D22 | H6: =Conservative!E22 | I6: =Optimistic!E22
A7: Your monthly earnings | B7: =Conservative!B43 | C7: =Optimistic!B43 | D7: =Conservative!C43 | E7: =Optimistic!C43 | F7: =Conservative!D43 | G7: =Optimistic!D43 | H7: =Conservative!E43 | I7: =Optimistic!E43
A8: Your annual earnings | B8: =Conservative!B44 | C8: =Optimistic!B44 | D8: =Conservative!C44 | E8: =Optimistic!C44 | F8: =Conservative!D44 | G8: =Optimistic!D44 | H8: =Conservative!E44 | I8: =Optimistic!E44
A9: Payout ratio | B9: =Conservative!B49 | C9: =Optimistic!B49 | D9: =Conservative!C49 | E9: =Optimistic!C49 | F9: =Conservative!D49 | G9: =Optimistic!D49 | H9: =Conservative!E49 | I9: =Optimistic!E49
A10: Company gross margin | B10: =Conservative!B57 | C10: =Optimistic!B57 | D10: =Conservative!C57 | E10: =Optimistic!C57 | F10: =Conservative!D57 | G10: =Optimistic!D57 | H10: =Conservative!E57 | I10: =Optimistic!E57
A11: Top 20 as % of commissions | B11: =Conservative!B67 | C11: =Optimistic!B67 | D11: =Conservative!C67 | E11: =Optimistic!C67 | F11: =Conservative!D67 | G11: =Optimistic!D67 | H11: =Conservative!E67 | I11: =Optimistic!E67
